<?xml version="1.0"?>
<robot name="ares_rover" xmlns:xacro="http://www.ros.org/wiki/xacro">
  <xacro:property name="mesh_package" value="package://ares_rover/meshes/" />

  <!-- Material Definitions -->
  <material name="mat_silver">
    <color rgba="0.8 0.8 0.8 1"/>
  </material>

  <!-- Base Link -->
  <link name="base_link">
    <inertial>
      <mass value="10"/>
      <inertia ixx="0.05" ixy="0" ixz="0" iyy="0.05" iyz="0" izz="0.1"/>
    </inertial>
    <visual>
      <origin xyz="0 0 0.495" rpy="0 0 0"/>
      <geometry>
        <mesh filename="${mesh_package}ares_body.stl" scale="1 1 1"/>
      </geometry>
      <material name="mat_silver"/>
    </visual>
    <collision>
      <origin xyz="0 0 0" rpy="0 0 0"/>
      <geometry>
        <box size="0.8 0.6 0.2"/> 
      </geometry>
    </collision>
  </link>

  <!-- Links (Arms) -->
  <!-- Left Link -->
  <link name="left_link">
    <inertial>
      <mass value="1"/>
      <inertia ixx="0.01" ixy="0" ixz="0" iyy="0.01" iyz="0" izz="0.02"/>
    </inertial>
    <visual>
      <origin xyz="0 0.278 0.422" rpy="0 -0 3.15"/>
      <geometry>
        <mesh filename="${mesh_package}ares_link.stl" scale="1 1 1"/>
      </geometry>
    </visual>
    <collision>
      <origin xyz="0 0 0" rpy="0 0 0"/>
      <geometry>
        <box size="0.7 0.1 0.1"/> 
      </geometry>
    </collision>
  </link>

  <!-- Right Link -->
  <link name="right_link">
    <inertial>
      <mass value="1"/>
      <inertia ixx="0.01" ixy="0" ixz="0" iyy="0.01" iyz="0" izz="0.02"/>
    </inertial>
    <visual>
      <origin xyz="0 -0.278 0.422" rpy="0 0 0"/>
      <geometry>
        <mesh filename="${mesh_package}ares_link.stl" scale="1 1 1"/>
      </geometry>
    </visual>
    <collision>
      <origin xyz="0 0 0" rpy="0 0 0"/>
      <geometry>
        <box size="0.7 0.1 0.1"/> 
      </geometry>
    </collision>
  </link>

  <!-- Joints between base_link and links -->
  <joint name="base_to_left_link" type="fixed">
    <parent link="base_link"/>
    <child link="left_link"/>
    <origin xyz="0 0 0" rpy="0 0 0"/>
  </joint>

  <joint name="base_to_right_link" type="fixed">
    <parent link="base_link"/>
    <child link="right_link"/>
    <origin xyz="0 0 0" rpy="0 0 0"/>
  </joint>

  <!-- Wheel Links -->
  <!-- Front Left Wheel -->
  <link name="front_left_wheel">
    <inertial>
      <mass value="0.5"/>
      <inertia ixx="0.002" ixy="0" ixz="0" iyy="0.002" iyz="0" izz="0.004"/>
    </inertial>
    <visual>
      <origin xyz="0.44 0.35 0.185" rpy="-0 0 -1.58"/>
      <geometry>
        <mesh filename="${mesh_package}ares_wheel.stl" scale="1 1 1"/>
      </geometry>
      <material name="mat_silver"/>
    </visual>
    <collision>
      <origin xyz="0.04 1 -0.3" rpy="1.5 0 0"/>
      <geometry>
        <cylinder radius="0.15" length="0.18"/> 
      </geometry>
    </collision>
  </link>

  <!-- Front Right Wheel -->
  <link name="front_right_wheel">
    <inertial>
      <mass value="0.5"/>
      <inertia ixx="0.002" ixy="0" ixz="0" iyy="0.002" iyz="0" izz="0.004"/>
    </inertial>
    <visual>
      <origin xyz="0.44 -0.3667 0.185" rpy="0 -0 1.569"/>
      <geometry>
        <mesh filename="${mesh_package}ares_wheel.stl" scale="1 1 1"/>
      </geometry>
      <material name="mat_silver"/>
    </visual>
    <collision>
      <origin xyz="0.04 -1 -0.3" rpy="1.5 0 0"/>
      <geometry>
        <cylinder radius="0.15" length="0.18"/> 
      </geometry>
    </collision>
  </link>

  <!-- Rear Left Wheel -->
  <link name="rear_left_wheel">
    <inertial>
      <mass value="0.5"/>
      <inertia ixx="0.002" ixy="0" ixz="0" iyy="0.002" iyz="0" izz="0.004"/>
    </inertial>
    <visual>
      <origin xyz="-0.43 0.3667 0.185" rpy="0 0 -1.58"/>
      <geometry>
        <mesh filename="${mesh_package}ares_wheel.stl" scale="1 1 1"/>
      </geometry>
      <material name="mat_silver"/>
    </visual>
    <collision>
      <origin xyz="-0.04 1 -0.3" rpy="1.5 0 0"/>
      <geometry>
        <cylinder radius="0.15" length="0.18"/> 
      </geometry>
    </collision>
  </link>

  <!-- Rear Right Wheel -->
  <link name="rear_right_wheel">
    <inertial>
      <mass value="0.5"/>
      <inertia ixx="0.002" ixy="0" ixz="0" iyy="0.002" iyz="0" izz="0.004"/>
    </inertial>
    <visual>
      <origin xyz="-0.44 -0.3667 0.185" rpy="0 -0 1.569"/>
      <geometry>
        <mesh filename="${mesh_package}ares_wheel.stl" scale="1 1 1"/>
      </geometry>
      <material name="mat_silver"/>
    </visual>
    <collision>
      <origin xyz="-0.04 -1 -0.3" rpy="1.5 0 0"/>
      <geometry>
        <cylinder radius="0.15" length="0.18"/> 
      </geometry>
    </collision>
  </link>

  <!-- Joints between links and wheels -->
  <!-- Each joint origin is set to the endpoint of the link to which the wheel is attached. -->
  <!-- Joint connecting left link to front left wheel -->
  <joint name="left_link_to_front_left_wheel_joint" type="continuous">
    <parent link="left_link"/>
    <child link="front_left_wheel"/>
    <origin xyz="0 0 0" rpy="0 0 0"/>
    <axis xyz="0 0 0"/>
  </joint>

  <!-- Joint connecting left link to rear left wheel -->
  <joint name="left_link_to_rear_left_wheel_joint" type="continuous">
    <parent link="left_link"/>
    <child link="rear_left_wheel"/>
    <origin xyz="0 0 0" rpy="0 0 0"/>
    <axis xyz="0 0 0"/>
  </joint>

  <!-- Joint connecting right link to front right wheel -->
  <joint name="right_link_to_front_right_wheel_joint" type="continuous">
    <parent link="right_link"/>
    <child link="front_right_wheel"/>
    <origin xyz="0 0 0" rpy="0 0 0"/>
    <axis xyz="0 0 0"/>
  </joint>

  <!-- Joint connecting right link to rear right wheel -->
  <joint name="right_link_to_rear_right_wheel_joint" type="continuous">
    <parent link="right_link"/>
    <child link="rear_right_wheel"/>
    <origin xyz="0 0 0" rpy="0 0 0"/>
    <axis xyz="0 0 0"/>
  </joint>

  <!-- Differential Drive Plugin -->
  <gazebo>
    <plugin name="differential_drive_controller" filename="libgazebo_ros_diff_drive.so">
      <rosDebugLevel>Debug</rosDebugLevel>
      <robotNamespace>/ares_rover</robotNamespace>
      <updateRate>100.0</updateRate>
      <leftJoint>left_link_to_front_left_wheel_joint</leftJoint>
      <rightJoint>right_link_to_front_right_wheel_joint</rightJoint>
      <wheelSeparation>0.4</wheelSeparation>
      <wheelDiameter>0.2</wheelDiameter>
      <torque>10</torque>
      <commandTopic>cmd_vel</commandTopic>
      <odometryTopic>odom</odometryTopic>
      <odometryFrame>odom</odometryFrame>
      <robotBaseFrame>base_link</robotBaseFrame>
    </plugin>
  </gazebo>

  <!-- Motor Plugins for Wheels -->
  <!-- Front Left Wheel Motor Plugin -->
  <gazebo>
    <plugin name="front_left_wheel_motor" filename="libgazebo_ros_control.so">
      <joint>left_link_to_front_left_wheel_joint</joint>
      <commandTopic>/ares_rover/front_left_wheel/command</commandTopic>
    </plugin>
  </gazebo>

  <!-- Front Right Wheel Motor Plugin -->
  <gazebo>
    <plugin name="front_right_wheel_motor" filename="libgazebo_ros_control.so">
      <joint>right_link_to_front_right_wheel_joint</joint>
      <commandTopic>/ares_rover/front_right_wheel/command</commandTopic>
    </plugin>
  </gazebo>

  <!-- Rear Left Wheel Motor Plugin -->
  <gazebo>
    <plugin name="rear_left_wheel_motor" filename="libgazebo_ros_control.so">
      <joint>left_link_to_rear_left_wheel_joint</joint>
      <commandTopic>/ares_rover/rear_left_wheel/command</commandTopic>
    </plugin>
  </gazebo>

  <!-- Rear Right Wheel Motor Plugin -->
  <gazebo>
    <plugin name="rear_right_wheel_motor" filename="libgazebo_ros_control.so">
      <joint>right_link_to_rear_right_wheel_joint</joint>
      <commandTopic>/ares_rover/rear_right_wheel/command</commandTopic>
    </plugin>
  </gazebo>

</robot>
